Workbook

Sheet Параметры
A1: ЭКОНОМИКА КЛИКЕРА v0.5 — входные параметры
A2: Синие ячейки крути. Кривая HP — полосная, до 50k (Стена Рагнарёка).
A4: ПОЛОСНАЯ КРИВАЯ HP (потолок 50k)
A5: HP моба уровень 1 | B5: 10 | C5: база
A6: Множ. HP полоса 1 (1-10k) | B6: 1.006 | C6: основной прогресс через ребёрты
A7: Множ. HP полоса 2 (10k-30k) | B7: 1.01 | C7: замедление
A8: Множ. HP полоса 3 (30k-45k) | B8: 1.02 | C8: очень тяжело
A9: Множ. HP полоса 4 (45k-50k) | B9: 1.05 | C9: практически стена
A10: Мобов на уровне | B10: 10 | C10: HP растёт МЕЖДУ уровнями, не внутри
A11: Множ. HP щит-босса (x500) | B11: 25
A12: Защита дневного босса | B12: 1000
A13: ЗОЛОТО (растёт вместе с HP)
A14: Золото за моба ур.1 | B14: 5
A15: Отставание золота от HP | B15: 0.97 | C15: золото = HP-множитель ^0.97 (нужен рост DPS)
A16: УРОН
A17: Базовый урон/тап | B17: 3
A18: Базовый DPS героя | B18: 2
A19: Множ. DPS за ур. героя | B19: 1.08 | C19: +8%/ур.
A20: Веха x5 (25/50/75/100) | B20: 5 | C20: разово если нет умения
A21: Веха x15 (каждые 500) | B21: 15
A22: Веха x25 (каждые 1000) | B22: 25
A23: Доп x25/1000 не-золотым | B23: 25 | C23: кристалльные/костровые/боги
A24: Бонус бафера/ур. | B24: 0.2 | C24: 15-25%
A25: Множ. особого бафера | B25: 3
A26: ПЕРЕРОЖДЕНИЕ
A27: Пепел за 1% DPS | B27: 0.003 | C27: 0.3% -> т.е. 0.003 Пепла за 1% прироста
A28: Макс. стартовый ур. (артефакт) | B28: 5000 | C28: очень дорогой апгрейд за Пепел
A29: ЦЕНЫ ГЕРОЕВ (золото)
A30: Цена 1-го героя | B30: 50
A31: Множ. цены найма | B31: 12
A32: Множ. цены апгрейда | B32: 1.07
A33: КОСТЁР (тяжёлый)
A34: Осколков T1 | B34: 100
A35: Осколков T2 | B35: 1000
A36: Осколков T3 | B36: 3000
A37: Осколков с 1 крист.героя | B37: 3
A38: РЕДКОСТЬ
A39: Уровней редкости | B39: 50 | C39: 5 рамок x 10
A40: Статы за ступень | B40: 0.05 | C40: +5%
A41: Возврат осколков за редкость | B41: 0.6 | C41: <1 = всегда меньше вложенного (не эксплойт)
...

Sheet Кривая до 50k
A1: ПОЛОСНАЯ КРИВАЯ HP ДО СТЕНЫ РАГНАРЁКА (50k)
A2: HP огромны — показываем log10(HP), т.е. «число из N цифр». Это же причина использовать big-number на бэкенде.
A4: Уровень | B4: log10(HP моба) | C4: HP ≈ | D4: Полоса | E4: Комментарий
A5: 1 | B5: 1 | C5: 10^1 | D5: полоса 1 | E5: старт
A6: 1000 | B6: 3.6 | C6: 10^4 | D6: полоса 1 | E6: основной прогресс
A7: 5000 | B7: 14 | C7: 10^14 | D7: полоса 1 | E7: основной прогресс
A8: 10000 | B8: 27 | C8: 10^27 | D8: полоса 1 | E8: основной прогресс
A9: 15000 | B9: 48.6 | C9: 10^49 | D9: полоса 2 | E9: замедление
A10: 20000 | B10: 70.2 | C10: 10^70 | D10: полоса 2 | E10: замедление
A11: 30000 | B11: 113.4 | C11: 10^113 | D11: полоса 2 | E11: замедление
A12: 35000 | B12: 156.4 | C12: 10^156 | D12: полоса 3 | E12: очень тяжело
A13: 40000 | B13: 199.4 | C13: 10^199 | D13: полоса 3 | E13: очень тяжело
A14: 45000 | B14: 242.4 | C14: 10^242 | D14: полоса 3 | E14: очень тяжело
A15: 48000 | B15: 306 | C15: 10^306 | D15: полоса 4 | E15: очень тяжело
A16: 50000 | B16: 348.4 | C16: 10^348 | D16: полоса 4 | E16: СТЕНА — практ. потолок
A18: ВАЖНО: log10(HP)=245 значит HP это число из 246 цифр. double ломается на ~10^308 (log10≈308). Уже к 48k HP близко к пределу double -> ОБЯЗАТЕЛЕН BigInteger/BigDecimal или мантисса+экспонента. Множители полос — синие в Параметрах, финал тюнится плейтестом.

Sheet Все герои (seed)
A1: ПОЛНЫЙ РОСТЕР ГЕРОЕВ — seed для БД
A3: ID | B3: Имя | C3: Группа | D3: Тип | E3: Умение | F3: Получение | G3: Цена | H3: Флаги
A4: 1 | B4: Трэлл | C4: стартовый | D4: актив | E4: Автотап (базовый) | F4: золото | G4: 50 gold
A5: 2 | B5: Рыбак с Лофотен | C5: стартовый | D5: актив | E5: Золото за тап по мобу/боссу | F5: золото | G5: экспонента
A6: 3 | B6: Скальд | C6: стартовый-бафер | D6: бафер | E6: +DPS всех героев за уровень (главный бафер) | F6: золото | G6: экспонента
A7: 4 | B7: Охотница фьордов | C7: стартовый | D7: пассив | E7: +крит-шанс тапа за уровень | F7: золото | G7: экспонента
A8: 5 | B8: Щитоносица | C8: стартовый | D8: пассив | E8: +общий DPS за уровень | F8: золото | G8: экспонента
A9: 6 | B9: Берсерк | C9: стартовый | D9: актив | E9: Дабл-дамаг: x2 на 10 сек (кд) | F9: золото | G9: экспонента | H9: эволюция->Аватар Ярости
A10: 7 | B10: Вёльва | C10: стартовый | D10: актив | E10: Сокращение КД всех умений | F10: золото | G10: экспонента | H10: эволюция->Пророчица
A11: 8 | B11: Гном Брокк | C11: стартовый | D11: пассив | E11: -цена улучшения героев | F11: золото | G11: экспонента
A12: 9 | B12: Ульфхеднар | C12: стартовый | D12: актив | E12: Каждый 10-й тап = x50 урон | F12: золото | G12: экспонента
A13: 10 | B13: Капитан драккара | C13: стартовый | D13: пассив | E13: +золото с боссов уровня | F13: золото | G13: экспонента
A14: 11 | B14: Эйнхерий | C14: стартовый-бафер | D14: бафер | E14: Усиливает эффект баферов (x3-бафер) | F14: золото | G14: экспонента
A15: 12 | B15: Валькирия-новобранец | C15: стартовый | D15: пассив | E15: +DPS за каждого открытого героя | F15: золото | G15: экспонента | H15: эволюция->Сигрдрива
A16: 13 | B16: Хульдра | C16: стартовый | D16: актив | E16: Усиление скилла (бафф активок) | F16: золото | G16: экспонента
A17: 14 | B17: Драуг | C17: стартовый | D17: пассив | E17: +DPS за убитых врагов (стак) | F17: золото | G17: экспонента | H17: эволюция->Король курганов
A18: 15 | B18: Ледяной ётун | C18: стартовый | D18: ребёрт | E18: ПЕРЕРОЖДЕНИЕ: сброс -> 0.3% Пепла | F18: золото | G18: экспонента | H18: НЕСЖИГАЕМ
A19: 16 | B19: Конунг-изгнанник | C19: скрытый | D19: пассив | E19: +25% урон тапа, аура +10% золота | F19: эволюция: Трэлл ур.1000 | G19: — | H19: замена Трэлла
A20: 17 | B20: Аватар Ярости | C20: скрытый | D20: актив | E20: Ярость x4 без кд, -20% золота | F20: эволюция: 500 Ярости | G20: — | H20: замена Берсерка
A21: 18 | B21: Пророчица Рагнарёка | C21: скрытый | D21: актив | E21: -15% кд команды, видит слабость | F21: эволюция: 1000-й этаж | G21: — | H21: замена Вёльвы
A22: 19 | B22: Король курганов | C22: скрытый | D22: пассив | E22: +DPS-миньоны (осады PvE) | F22: эволюция: 1 млн убийств | G22: — | H22: замена Драуга
A23: 20 | B23: Сигрдрива | C23: скрытый | D23: пассив | E23: +DPS за героя, воскрешение в PvE | F23: эволюция: 7 боссов | G23: — | H23: замена Валькирии
A24: 21 | B24: Рататоск | C24: кристалльный | D24: актив | E24: Ворует 5% HP босса раз в 30 сек | F24: кристаллы | G24: — | H24: активация
A25: 22 | B25: Хугин и Мунин | C25: кристалльный | D25: пассив | E25: Раскрывают защитников, +10% урона | F25: кристаллы | G25: — | H25: активация
A26: 23 | B26: Кот Фрейи | C26: кристалльный | D26: пассив | E26: +50% золота оффлайн | F26: кристаллы | G26: — | H26: активация
A27: 24 | B27: Тангниостр | C27: кристалльный | D27: актив | E27: Сброс кд всей команды раз в бой | F27: кристаллы | G27: — | H27: активация
A28: 25 | B28: Мимир (голова) | C28: кристалльный | D28: пассив | E28: +1 выбор умения, +10% опыта | F28: кристаллы | G28: — | H28: активация
... A47: 44 | B47: Последний Эйнхерий | C47: костёр T3 | D47: пассив | E47: Бессмертие 30 сек (PvE) | F47: 1000 оск + 2 T2 | G47: — | H47: топ костра

Sheet Цены героев
A1: ЦЕНЫ НЕ-ЗОЛОТЫХ ГЕРОЕВ
A3: Герой | B3: Группа | C3: Валюта | D3: Цена
A4: Рататоск | B4: кристалльный | C4: кристаллы | D4: 500
A5: Хугин и Мунин | B5: кристалльный | C5: кристаллы | D5: 800
A6: Кот Фрейи | B6: кристалльный | C6: кристаллы | D6: 1200
A7: Тангниостр | B7: кристалльный | C7: кристаллы | D7: 2000
A8: Мимир (голова) | B8: кристалльный | C8: кристаллы | D8: 3500
A9: Гача-пул (1 пулл) | B9: гача | C9: кристаллы | D9: 1000
A10: Костёр T1 (осколки) | B10: костёр | C10: осколки | D10: 100
A11: Костёр T2 | B11: костёр | C11: осколки | D11: 1000
A12: Костёр T3 | B12: костёр | C12: осколки | D12: 3000

Sheet Гача-дропрейты
A1: ГАЧА-ПАК (1000 кристаллов/пулл) — прозрачные шансы
A3: Редкость | B3: Шанс | C3: Пул героев | D3: Pity
A4: Редкий | B4: 70% | C4: Гуллинбурсти, Модгуд, Скирнир | D4: —
A5: Эпик | B5: 25% | C5: Вёлунд, Урд, Верданди, Эгир, Ран | D5: —
A6: Легенда | B6: 5% | C6: Скульд, Свартхёфди | D6: гарантия на 50-м пулле
A8: Прозрачные дропрейты — часть честных правил (видны в UI).

Sheet Осколки с боссов
A1: ВЫХОД ОСКОЛКОВ (недельные PvE-боссы)
A2: shards = floor(baseShards × damageShare × tierMult). damageShare = твой урон / урон клана.
A4: Босс | B4: baseShards/нед | C4: tierMult | D4: Осколков при 10% вклада
A5: Скёлль | B5: 300 | C5: 1 | D5: =ROUND(B5*0.1*C5,0) -> 30
A6: Кракен Эгира | B6: 300 | C6: 1.1 | D6: =ROUND(B6*0.1*C6,0) -> 33
A7: Гарм | B7: 350 | C7: 1.1 | D7: =ROUND(B7*0.1*C7,0) -> 39
A8: Логи | B8: 350 | C8: 1.2 | D8: =ROUND(B8*0.1*C8,0) -> 42
A9: Нидхёгг | B9: 400 | C9: 1.3 | D9: =ROUND(B9*0.1*C9,0) -> 52
A10: Имир | B10: 450 | C10: 1.4 | D10: =ROUND(B10*0.1*C10,0) -> 63
A11: Хресвельг-старший | B11: 500 | C11: 1.5 | D11: =ROUND(B11*0.1*C11,0) -> 75

Sheet Костёр
A1: ПИРАМИДА КОСТРА (T2-T3 только на костре 5000+)
A4: Ступень | B4: Осколков на 1 героя | C4: Пояснение
A5: Крист. герой (база) | B5: 1 | C5: покупка за кристаллы
A6: Костёр T1 | B6: =Параметры!$B$34 -> 100 | C6: жжём крист.героев -> осколки
A7: Костёр T2 | B7: =Параметры!$B$35 -> 1000 | C7: только улучшенный костёр (5000 ур.)
A8: Костёр T3 (топ) | B8: =Параметры!$B$36 -> 3000 | C8: верхушка соло-прогресса

Sheet Герои и вехи
A1: ВЕХИ-МНОЖИТЕЛИ (у всех героев)
A3: Веха (ур. героя) | B3: Эффект | C3: Множитель | D3: Примечание
A4: 25 / 50 / 75 / 100 | B4: доп.умение ИЛИ разовый ×5 DPS | C4: =Параметры!$B$20 -> 5 | D4: если у героя нет умения на этой вехе
A5: каждые 500 | B5: ×15 DPS | C5: =Параметры!$B$21 -> 15 | D5: стакается
A6: каждые 1000 | B6: ×25 DPS | C6: =Параметры!$B$22 -> 25 | D6: стакается
A7: каждые 1000 (бонус) | B7: доп ×25 — НЕ-золотым | C7: =Параметры!$B$23 -> 25 | D7: кристалльные/костровые/боги
A9: Пример: не-золотой герой на ур.1000 = ×15(500-вехи ×2) ... ×25 ×25(бонус) — кратно сильнее золотого. Точный стек тюнится.

Sheet Артефакты
A1: АРТЕФАКТЫ — эффект и кривая цены
A2: costLevel(n) = base × growth^n (Пепел). Дуэльные — за Короны.
A4: Артефакт | B4: Валюта | C4: Эффект/ур. | D4: База цены | E4: Рост цены | F4: Макс ур.
A5: Урон за тап | B5: Пепел | C5: +10% | D5: 10 | E5: 1.35 | F5: ∞
A6: DPS в секунду | B6: Пепел | C6: +10% | D6: 10 | E6: 1.35 | F6: ∞
A7: Цена героев | B7: Пепел | C7: −2% | D7: 50 | E7: 1.5 | F7: 50
A8: Золото с монстров | B8: Пепел | C8: +8% | D8: 15 | E8: 1.4 | F8: ∞
A9: Больше Пепла | B9: Пепел | C9: +5% | D9: 100 | E9: 1.6 | F9: ∞
A10: Меньше мобов 10→5 | B10: Пепел | C10: −1 моб | D10: 5000 | E10: 3 | F10: 5
A11: Старт-ур. ребёрта | B11: Пепел | C11: +1000 ур. | D11: 20000 | E11: 4 | F11: 5
A12: Дуэль: +HP | B12: Короны | C12: +8% | D12: 20 | E12: 1.4 | F12: ∞
A13: Дуэль: +крит | B13: Короны | C13: +3% | D13: 20 | E13: 1.4 | F13: ∞
A14: Дуэль: +броня | B14: Короны | C14: +8% | D14: 20 | E14: 1.4 | F14: ∞
A15: Дуэль: +регенерация | B15: Короны | C15: +5% | D15: 25 | E15: 1.4 | F15: ∞

Sheet Шахты
A1: ШАХТЫ — открытие и добыча
A3: Шахта | B3: Открытие (ур.) | C3: Кристаллов/час | D3: Занято героев
A4: Шахта 1 | B4: 100 | C4: 20 | D4: 3
A5: Шахта 2 | B5: 500 | C5: 35 | D5: 3
A6: Шахта 3 | B6: 1500 | C6: 60 | D6: 3
A7: Шахта 4 | B7: 3000 | C7: 100 | D7: 3
A9: Слот редкости: герой раз в 24ч растит редкость, −50% силы пока внутри. VIP3 даёт +1 слот шахты.

Sheet Яблоки-траты
A1: ЯБЛОКИ ИДУНН — стоимость действий
A3: Действие | B3: Цена (Яблоки) | C3: Эффект
A4: Воскрешение 3 героев | B4: 100 | C4: мгновенно вернуть убитых боссом
A5: Сброс КД дуэлей | B5: 150 | C5: снова 5 дуэлей
A6: Сброс КД умений | B6: 50 | C6: обнулить кулдауны скиллов
A7: Сброс КД ежедн. заданий | B7: 80 | C7: повторить дейлики
A8: Сброс КД дневного босса | B8: 50 | C8: растёт ×2.5 за сброс (см. Параметры)
A9: Путешествие 5 ч | B9: 120 | C9: мгновенный оффлайн-доход за 5ч
A10: Путешествие 50 ч | B10: 900 | C10: мгновенный оффлайн-доход за 50ч
A11: Золото за 5 ч | B11: 100 | C11: выдать золото как за 5ч фарма
A12: Золото за 50 ч | B12: 800 | C12: как за 50ч
A13: ×2 DPS на 5 ч | B13: 150 | C13: буст урона
A14: ×2 DPS на 50 ч | B14: 1000 | C14: буст урона
A15: Пак героев | B15: 1000 | C15: шанс редкого/донат-героя

Sheet Боги-таблица
A1: ПАНТЕОН — 10 богов: тир, доступ, цена, родословная
A3: Бог | B3: Тир ⭐ | C3: Ступень доступа | D3: Цена (Слёзы) | E3: Цена ($) | F3: Родитель (порядок) | G3: Ниша
A4: Локи | B4: ⭐⭐⭐⭐ | C4: костёр + Слёзы | D4: 15 | E4: =D4*Параметры!$B$52 -> 150 | F4: — | G4: анти-босс дебафф / прародитель
A5: Хель | B5: ⭐⭐⭐⭐ | C5: костёр + Слёзы | D5: 15 | E5: =D5*Параметры!$B$52 -> 150 | F5: — | G5: контроль / замедление
A6: Бальдр | B6: ⭐⭐⭐⭐ | C6: костёр + Слёзы | D6: 20 | E6: =D6*Параметры!$B$52 -> 200 | F6: — | G6: саппорт / защита
A7: Хеймдалль | B7: ⭐⭐⭐⭐⭐ | C7: костёр T2+ / Слёзы | D7: 40 | E7: =D7*Параметры!$B$52 -> 400 | F7: — | G7: страж / анти-щит
A8: Тюр | B8: ⭐⭐⭐⭐⭐ | C8: костёр T2+ / Слёзы | D8: 40 | E8: =D8*Параметры!$B$52 -> 400 | F8: — | G8: пробитие брони
A9: Ёрмунганд | B9: ⭐⭐⭐⭐⭐ | C9: костёр T2+ / Слёзы | D9: 60 | E9: =D9*Параметры!$B$52 -> 600 | F9: Локи | G9: разрушение крепостей
A10: Фенрир | B10: ⭐⭐⭐⭐⭐⭐ | C10: донат | D10: 120 | E10: =D10*Параметры!$B$52 -> 1200 | F10: Локи | G10: лучший против боссов
A11: Тор | B11: ⭐⭐⭐⭐⭐⭐ | C11: донат | D11: 150 | E11: =D11*Параметры!$B$52 -> 1500 | F11: Один | G11: главный постоянный DPS
A12: Сурт | B12: ⭐⭐⭐⭐⭐⭐⭐ | C12: донат | D12: 280 | E12: =D12*Параметры!$B$52 -> 2800 | F12: — | G12: массовый урон
A13: Один | B13: ⭐⭐⭐⭐⭐⭐⭐⭐ | C13: донат | D13: 500 | E13: =D13*Параметры!$B$52 -> 5000 | F13: Тор+Бальдр | G13: универсал-лидер, усиливает состав
A15: Жёлтый = 5⭐ (дорогой костёр). Оранжевый = 6-8⭐ (донат-витрина). Цена $ считается из Параметров.

Sheet Боги-баланс
A1: ФРИ-ФАРМ СЛЁЗ (очень строгий: 2/нед)
A3: Показатель | B3: Значение | C3: Ед.
A5: Фарм Слёз в неделю (потолок) | B5: 2 | C5: /нед
A6: Дешёвый бог (4⭐) | B6: 15 | C6: Слёз
A7: Недель на 4⭐ бога | B7: =B6/B5 -> 7.5 | C7: нед
A8: Один (топ) | B8: 500 | C8: Слёз
A9: Недель на Одина | B9: =B8/B5 -> 250 | C9: нед
A10: Лет на Одина (фри) | B10: =B9/52 -> 4.8076923 | C10: лет
A11: Купленный | B11: мгновенно

Sheet Донат
A1: СЛЁЗЫ ФРЕЙИ — донат-валюта
A4: Показатель | B4: Значение | C4: Ед.
A5: Цена 1 Слезы | B5: =Параметры!$B$52 -> 10 | C5: $
A6: Дешёвый бог | B6: =Параметры!$B$54*Параметры!$B$52 -> 10 | C6: $
A7: Дорогой бог | B7: =Параметры!$B$55*Параметры!$B$52 -> 5000 | C7: $
A8: Опт-скидка (макс) | B8: =Параметры!$B$53 -> 0.25 | C8: %
A9: Дорогой бог со скидкой | B9: =B7*(1-Параметры!$B$53) -> 3750 | C9: $
A10: Платящий получает бога | B10: =IF(Параметры!$B$56=1,"СРАЗУ","гейт") -> СРАЗУ

Sheet Монетизация
A1: ПАКИ И ЦЕНЫ
A3: SKU | B3: Содержимое | C3: Цена $ | D3: Скидка
A4: tears_1 | B4: 1 Слеза Фрейи | C4: $10 | D4: —
A5: tears_5 | B5: 5 Слёз | C5: $45 | D5: −10%
A6: tears_15 | B6: 15 Слёз | C6: $120 | D6: −20%
A7: tears_60 | B7: 60 Слёз | C7: $450 | D7: −25%
A8: vip | B8: VIP (5 ур., разово) | C8: $50 | D8: —
A9: season_pass | B9: Сезон-пропуск | C9: $10 | D9: —
A10: starter | B10: Стартовый бандл (разово) | C10: $5 | D10: high value
A11: crystals_pack | B11: Пак кристаллов | C11: $10 | D11: —
A12: apples_pack | B12: Пак Яблок | C12: $10 | D12: —

Sheet VIP
A1: VIP — 5 уровней (1 покупка)
A3: Ур. | B3: Яблок/нед. | C3: +Золото | D3: +Пепел | E3: Прочее
A4: 1 | B4: 50 | C4: 5% | D4: 5% | E4: авто-сбор оффлайна
A5: 2 | B5: 100 | C5: 10% | D5: 10% | E5: +потолок оффлайна
A6: 3 | B6: 175 | C6: 15% | D6: 15% | E6: +1 слот шахты
A7: 4 | B7: 275 | C7: 20% | D7: 20% | E7: -20% цена сброса дневного босса
A8: 5 | B8: 400 | C8: 30% | D8: 25% | E8: все бонусы + уник. рамка

Sheet Осадные боссы (PvE)
A1: МИРОВЫЕ PvE-БОССЫ — 1 НЕДЕЛЯ на босса (7-недельный цикл)
A3: Неделя цикла | B3: Босс | C3: Заменил | D3: Защитники | E3: Награда | F3: Окно
A4: Неделя 1 | B4: Скёлль | C4: Фенрира | D4: волчья стая | E4: осколки | F4: 7 дней, клан вместе
A5: Неделя 2 | B5: Кракен Эгира | C5: Ёрмунганда | D5: морские твари | E5: осколки | F5: 7 дней
A6: Неделя 3 | B6: Гарм | C6: Хель | D6: стражи Гнипахеллира | E6: осколки | F6: 7 дней
A7: Неделя 4 | B7: Логи | C7: Сурта | D7: искровые духи | E7: осколки | F7: 7 дней
A8: Неделя 5 | B8: Нидхёгг | C8: — | D8: змеи корней | E8: осколки | F8: 7 дней
A9: Неделя 6 | B9: Имир | C9: — | D9: хримтурсы | E9: осколки | F9: 7 дней
A10: Неделя 7 | B10: Хресвельг-старший | C10: — | D10: ветряные духи | E10: осколки | F10: 7 дней, затем цикл
A12: 1 босс = 1 неделя (не день). Клан всю неделю валит одного мирового босса. Награда — только осколки/ресурсы, НЕ боги.
